Workbook

Sheet Homework Questions
B1: These two questions should be completed BEFORE your tutorial. You attempts should be submitted on Moodle.
B3: QUESTION 1
B4: For the 2024-25 income year, STAMP Australia Pty Limited has assessable income of $49,000,000 and deductions of $32,500,000. The company made a tax loss of $1,250,000 in the 2020-21 income year. All income is derived from its business activities.
B6: Calculate STAMP Australia Pty Limited's total income tax liability to the ATO for the 2023-24 income year.
B8: Solution: | C8: Workings: | D8: Answer:
B9: Taxable income = | C9: ? | D9: ?
B10: However, assuming the company meets either the 'continuity of ownership' test or 'similar business' test, it can deduct the tax loss incurred in the 2020-21 income year.
B11: Therefore, taxable income = | C11: ? | D11: ?
B12: The company's revenue (turnover) is less than $50m and it does not have any passive income, so it qualifies as a 'base rate entity'.
B13: Therefore, tax payable = | C13: ? | D13: ?
B15: QUESTION 2
B16: Loggo Sports Australia Pty Limited is an online retail company selling sporting equipment. In the 2024-25 income year it has the following items in its Profit and Loss Statement:
B17: · Turnover - $75,600,000
B18: · Total expenses - $48,200,000. Included in this amount is depreciation expense of $8,200,000, customer entertainment expenses of $500,000, and fines and penalties of $75,000.
B20: The company’s financial controller has calculated that the decline in value of the depreciable assets is $10,125,000. Assume that 100% of the turnover constitutes assessable income for tax purposes and that all assessable income is derived by its business activities.
B22: Calculate the tax liability of Loggo Sports Australia Pty Limited for the 2024-25 income year.
B23: Loggo Sports Australia Pty Limited (LSA) is not a ‘base rate entity’ as its turnover exceeds the threshold of $50m. Therefore, LSA is taxed at 30%.
B25: Assessable income (turnover) | C25: ?
B26: Less expenses: | C26: ?
C27: ?
B28: Add back:
B29: ? | C29: ?
B30: ? | C30: ?
B31: ? | C31: ?
C32: ?
B33: Less:
B34: ? | C34: ?
B35: Taxable income | C35: ?
B36: Tax payable @ 30% | C36: ?

Sheet Video Activity
B1: These questions will be completed in your tutorial. You do NOT need to submit this via Moodle.
B3: QUESTION 1
B4: Prime and Mark Pty Limited (P&M) is the owner of two discount retail shops selling cheap clothing. P&M is also the beneficiary of a discretionary trust which earns rental income from owning commercial properties and interest income earned on term deposits. All the investment income earned by the trust is distributed to P&M. In the 2024-25 income year, P&M has:
B5: · Aggregated turnover (revenue) of $49,500,000
B6: · Assessable income of $48,000,000 comprising $40,800,000 investment income attributable to the trust distribution and $7,200,000 of trading income from running the business.
B8: What tax rate will be applied to P&M’s taxable income in the 2024-25 income year?
B10: Solution:
B12: P&M meets the first test under s23AA Income Tax Rates Act 1986 i.e., aggregated turnover < $50m threshold but it fails the second test because 85% ($40,800,000 / $48,000,000) of its assessable income is base rate entity passive income which is greater than the 80% threshold allowed in s23AA Income Tax Rates Act 1986.
B14: QUESTION 2
B15: XYZ Pty Limited incurred a tax loss in the 2022 income year. Andrew, Michael and Belinda owned shares in XYZ Pty Limited as shown in the table below.
B16: Shareholder | C16: Shareholding from 1 July 2021 to 17 September 2022 | D16: Shareholding from 18 September 2022 to 30 June 2024
B18: Andrew | C18: 0.4 | D18: 0.1
B19: Michael | C19: 0.4 | D19: 0.1
B20: Belinda | C20: 0.2 | D20: 0.8
B21: Total | C21: 1 | D21: 1
B23: On 18 September 2022, both Andrew and Michael sold 75% of their shareholding in XYZ Pty Limited to Belinda.
B24: XYZ Pty Limited is seeking to deduct a tax loss in the 2024-5 income year. Will XYZ Pty Limited satisfy the continuity of ownership test?
B26: Solution:
B27: 1 July 2021 to 30 June 2022 = ‘loss year’
B28: 1 July 2024 to 30 June 2025 = ‘income year’
B29: Andrew/Michael shareholding change = | E29: ?
B31: XYZ Pty Limited is seeking to deduct a tax loss in the 2024-5 income year. Will XYZ Pty Limited satisfy the continuity of ownership test?
B32: ?
B34: Shareholder | C34: Shareholding from 1 July 2021 to 17 September 2022 | D34: Shareholding from 18 September 2022 to 30 June 2025 | E34: Percentage counted towards continuity of ownership test
B36: Andrew | C36: 0.4 | D36: 0.1 | E36: ?
B37: Michael | C37: 0.4 | D37: 0.1 | E37: ?
B38: Belinda | C38: 0.2 | D38: 0.8 | E38: ?
B39: Total | C39: 1 | D39: 1 | E39: ?

Sheet Tutorial Activity
B1: These questions will be completed in your tutorial. You do NOT need to submit this via Moodle.
B4: Background The Tax Laws Amendment (2013 Measures No.2) Act 2013 was introduced into the Australian Parliament in 2013 and mandated disclosure by the Australian Taxation Office (ATO) of certain information from the tax returns of large Australian corporations. The aims include: (i) a general aim of informing the public debate about corporate tax policy and (ii) a specific aim of providing information about the tax affairs of large corporations and facilitating public scrutiny of the tax strategies being adopted. The intention is that increased public scrutiny will constrain aggressive tax strategies. The first disclosures by the ATO relating to the tax year (1 July 2013 to 30 June 2014) were made on 17 December 2015 and subsequent disclosures have been made annually in November or December every year. The disclosures result in intense media scrutiny. For the 2022-23 income year and onwards, the information is published for: • any corporate tax entity that has total income equal to or exceeding $100 million • entities that have petroleum resource rent tax (PRRT) payable The data is disclosed by the ATO in a report called the ‘Report of Entity Tax Information’. Data sources (x 3) 1. ‘Total income’: an accounting system amount that generally corresponds to the relevant amount in the entity’s financial statements (most income received when carrying on a business is assessable for income tax purposes i.e., assessable income). 2. ‘Taxable income’: the difference between assessable income and deductions. 3. ‘Tax payable’: multiplying the taxable income by the 30% corporate tax rate and then deducting tax offset and credits e.g., research and development (R&D) incentive.
B6: Exercise The objective of this exercise is to broadly evaluate the tax practices of several large multinationals using data published in the most recent Report of Entity Tax Information relating to the 2021-22 income year published in late 2023.
B8: Step 1: Access the spreadsheet which contains an extract of the data for 5 companies (see last tab called "Companies for analysis").
B9: Step 2: Calculate the effective tax rate (ETR). ETR = tax payable / taxable income.
B10: Step 3: Obtain the 2022 Annual Report for Cochlear Limited, Flight Centre Limited and Qantas Airways Limited and review the Profit & Loss Statement (Income Statement) and Income Tax note for clues explaining their low ETR.
B11: Step 4: Discuss the possible reasons for differences across the 5 firms.
B12: Step 5: Calculate the ETR and the ratio of taxable income to total income for the 5 foreign owned Australian subsidiaries and 3 ASX listed firms and answer the following questions:
B14: 1. What is the difference between Pty Limited (or Pty Ltd) and Limited (or LTD)?
B15: 2. What is the main difference between the 5 foreign owned subsidiaries compared to the 3 ASX listed firms?
B17: The report is available at: https://data.gov.au/data/dataset/corporate-transparency and has been uploaded to Moodle. The last worksheet (tab) in the spreadsheet contains the companies for analysis - the tab is called "Companies for analysis".

Sheet Tutorial Activity Template
B1: Background The Tax Laws Amendment (2013 Measures No.2) Act 2013 was introduced into the Australian Parliament in 2013 and mandated disclosure by the Australian Taxation Office (ATO) of certain information from the tax returns of large Australian corporations. The aims include: (i) a general aim of informing the public debate about corporate tax policy and (ii) a specific aim of providing information about the tax affairs of large corporations and facilitating public scrutiny of the tax strategies being adopted. The intention is that increased public scrutiny will constrain aggressive tax strategies. The first disclosures by the ATO relating to the tax year (1 July 2013 to 30 June 2014) were made on 17 December 2015 and subsequent disclosures have been made annually in November or December every year. The disclosures result in intense media scrutiny. For the 2022-23 income year and onwards, the information is published for: • any corporate tax entity that has total income equal to or exceeding $100 million • entities that have petroleum resource rent tax (PRRT) payable The data is disclosed by the ATO in a report called the ‘Report of Entity Tax Information’. Data sources (x 3) 1. ‘Total income’: an accounting system amount that generally corresponds to the relevant amount in the entity’s financial statements (most income received when carrying on a business is assessable for income tax purposes i.e., assessable income). 2. ‘Taxable income’: the difference between assessable income and deductions. 3. ‘Tax payable’: multiplying the taxable income by the 30% corporate tax rate and then deducting tax offset and credits e.g., research and development (R&D) incentive.
B3: Exercise The objective of this exercise is to broadly evaluate the tax practices of several large multinationals using data published in the most recent Report of Entity Tax Information relating to the 2021-22 income year published in late 2023.
B5: Step 1: Access the spreadsheet which contains an extract of the data for 5 companies.
B6: Step 2: Calculate the effective tax rate (ETR). ETR = tax payable / taxable income.
B8: Name | C8: ABN | D8: Total income $ | E8: Taxable income $ | F8: Tax payable $ | G8: Income year | H8: Effective tax rate | I8: Ratio of Taxable income to Total Income
B9: COCHLEAR LIMITED | C9: 96002618073 | D9: =VLOOKUP($B9,'Income tax details'!$A:$F,3,0) -> 1296859592 | E9: =VLOOKUP($B9,'Income tax details'!$A:$F,4,0) -> 368140606 | F9: =VLOOKUP($B9,'Income tax details'!$A:$F,5,0) -> 13616051 | G9: =VLOOKUP($B9,'Income tax details'!$A:$F,6,0) -> 2021-22 | H9: =F9/E9 -> 0.036986007 | I9: =E9/D9 -> 0.28387083
B10: FLIGHT CENTRE TRAVEL GROUP LIMITED | C10: 25003377188 | D10: =VLOOKUP($B10,'Income tax details'!$A:$F,3,0) -> 495634399 | E10: =VLOOKUP($B10,'Income tax details'!$A:$F,4,0) -> 0 | F10: =VLOOKUP($B10,'Income tax details'!$A:$F,5,0) -> 0 | G10: =VLOOKUP($B10,'Income tax details'!$A:$F,6,0) -> 2021-22 | H10: =F10/E10 -> #DIV/0! | I10: =E10/D10 -> 0
B11: JB HI-FI LIMITED | C11: 80093220136 | D11: =VLOOKUP($B11,'Income tax details'!$A:$F,3,0) -> 8990822883 | E11: =VLOOKUP($B11,'Income tax details'!$A:$F,4,0) -> 765954031 | F11: =VLOOKUP($B11,'Income tax details'!$A:$F,5,0) -> 229786059 | G11: =VLOOKUP($B11,'Income tax details'!$A:$F,6,0) -> 2021-22 | H11: =F11/E11 -> 0.2999998 | I11: =E11/D11 -> 0.085192873
B12: QANTAS AIRWAYS LIMITED | C12: 16009661901 | D12: =VLOOKUP($B12,'Income tax details'!$A:$F,3,0) -> 9324605379 | E12: =VLOOKUP($B12,'Income tax details'!$A:$F,4,0) -> 0 | F12: =VLOOKUP($B12,'Income tax details'!$A:$F,5,0) -> 0 | G12: =VLOOKUP($B12,'Income tax details'!$A:$F,6,0) -> 2021-22 | H12: =F12/E12 -> #DIV/0! | I12: =E12/D12 -> 0
B13: WOOLWORTHS GROUP LIMITED | C13: 88000014675 | D13: =VLOOKUP($B13,'Income tax details'!$A:$F,3,0) -> 58136662436 | E13: =VLOOKUP($B13,'Income tax details'!$A:$F,4,0) -> 1610082986 | F13: =VLOOKUP($B13,'Income tax details'!$A:$F,5,0) -> 460957826 | G13: =VLOOKUP($B13,'Income tax details'!$A:$F,6,0) -> 2021-22 | H13: =F13/E13 -> 0.28629445 | I13: =E13/D13 -> 0.027694796
B15: Step 3: Obtain the 2022 Annual Report for Cochlear Limited, Flight Centre Limited and Qantas Airways Limited and review the Profit & Loss Statement (Income Statement) and Income Tax note for clues explaining their low ETR.
B17: Cochlear: | C17: R&D Tax Incentive
B18: Flight Centre: | C18: COVID Tax Losses
B19: QANTAS: | C19: COVID Tax Losses
B21: Step 4: Discuss the possible reasons for differences across the 5 firms.
B23: General Reasons:
B24: Different depreciation
B25: Accounting income \neq taxable income
B26: Loss carry-forwards can reduce taxable income to zero
B27: Non-assessable income/non-deductible expenses
B28: R&D incentives
B29: Foreign income with overases tax credits
B35: 1. Industry | C35: 2
B36: Cochlear Limited - medical devices
B37: Flight Centre Travel Group Limited - travel agency
B38: JB Hi-Fi Limited - retail
B39: Qantas Airways Limited - aviation
B40: Woolworths Group Limited - supermarkets/retail
B43: 3. Tax Deductions & Expenses | C43: 4
B50: 5 | C50: 6
B58: Step 5: Calculate the ETR and the ratio of taxable income to total income for the 5 foreign owned Australian subsidiaries and 3 ASX listed firms and answer the following questions:
B60: Name | C60: ABN | D60: Total income $ | E60: Taxable income $ | F60: Tax payable $ | G60: Income year | H60: Effective tax rate | I60: Ratio of Taxable income to Total Income
B61: Foreign owned Australian subsidiaries:
B62: APPLE PTY LTD | C62: 46002510054 | D62: =VLOOKUP($B62,'Income tax details'!$A:$F,3,0) -> 9335050508 | E62: =VLOOKUP($B62,'Income tax details'!$A:$F,4,0) -> 458656103 | F62: =VLOOKUP($B62,'Income tax details'!$A:$F,5,0) -> 137312506 | G62: =VLOOKUP($B62,'Income tax details'!$A:$F,6,0) -> 2021-22 | H62: =F62/E62 -> 0.29938009 | I62: =E62/D62 -> 0.049132686
B63: ASTRAZENECA HOLDINGS PTY LIMITED | C63: 59066876962 | D63: =VLOOKUP($B63,'Income tax details'!$A:$F,3,0) -> 1085127894 | E63: =VLOOKUP($B63,'Income tax details'!$A:$F,4,0) -> 155685431 | F63: =VLOOKUP($B63,'Income tax details'!$A:$F,5,0) -> 40390847 | G63: =VLOOKUP($B63,'Income tax details'!$A:$F,6,0) -> 2021-22 | H63: =F63/E63 -> 0.25943884 | I63: =E63/D63 -> 0.14347196
B64: FACEBOOK AUSTRALIA PTY LIMITED | C64: 83134012543 | D64: =VLOOKUP($B64,'Income tax details'!$A:$F,3,0) -> 1147348081 | E64: =VLOOKUP($B64,'Income tax details'!$A:$F,4,0) -> 100584537 | F64: =VLOOKUP($B64,'Income tax details'!$A:$F,5,0) -> 30175361 | G64: =VLOOKUP($B64,'Income tax details'!$A:$F,6,0) -> 2021-22 | H64: =F64/E64 -> 0.3 | I64: =E64/D64 -> 0.087666976
B65: GOOGLE AUSTRALIA PTY LIMITED | C65: 33102417032 | D65: =VLOOKUP($B65,'Income tax details'!$A:$F,3,0) -> 1789056238 | E65: =VLOOKUP($B65,'Income tax details'!$A:$F,4,0) -> 325873549 | F65: =VLOOKUP($B65,'Income tax details'!$A:$F,5,0) -> 83263425 | G65: =VLOOKUP($B65,'Income tax details'!$A:$F,6,0) -> 2021-22 | H65: =F65/E65 -> 0.25550839 | I65: =E65/D65 -> 0.1821483
B66: MICROSOFT PTY LTD | C66: 29002589460 | D66: =VLOOKUP($B66,'Income tax details'!$A:$F,3,0) -> 6296619602 | E66: =VLOOKUP($B66,'Income tax details'!$A:$F,4,0) -> 400935241 | F66: =VLOOKUP($B66,'Income tax details'!$A:$F,5,0) -> 120280572 | G66: =VLOOKUP($B66,'Income tax details'!$A:$F,6,0) -> 2021-22 | H66: =F66/E66 -> 0.3 | I66: =E66/D66 -> 0.06367468
B68: ASX listed firms:
B69: BHP GROUP LIMITED | C69: 49004028077 | D69: =VLOOKUP($B69,'Income tax details'!$A:$F,3,0) -> 87387398006 | E69: =VLOOKUP($B69,'Income tax details'!$A:$F,4,0) -> 40298379937 | F69: =VLOOKUP($B69,'Income tax details'!$A:$F,5,0) -> 9483568682 | G69: =VLOOKUP($B69,'Income tax details'!$A:$F,6,0) -> 2021-22 | H69: =F69/E69 -> 0.23533375 | I69: =E69/D69 -> 0.46114635
...

Sheet Information
A1: Corporate tax transparency: report of entity tax information
A2: To better inform public debate about tax policy, the Commissioner is required by legislation to produce an annual report of information about certain corporate tax entities. This annual report lists public and foreign-owned corporations (including foreign-owned private corporations) with total income of $100 million or more, as well as Australian-owned resident private corporations with total income of $200 million or more, in tax returns for the 2021-22 income year. This report also includes late lodging corporations meeting these requirements whose information was not available by the cut-off date (1 September each year) to produce the 2019-20 and 2020-21 Report of Entity Tax Information (first link below). Due to legislative limits on the information able to be included, this entity by entity level report does not reflect actual economic or accounting groupings. It is important to note the aggregate figures listed cannot and do not reflect the complexity of the tax system. This report is intended to be read in conjunction with guidance material available on ato.gov.au which provides context around the demographics of entities included in this report and both taxable income and tax payable amounts (second link below). Please note: As the legislation does not allow for the reporting of an amount of zero or less, these fields are left blank. A separate tab lists the details of entities that have petroleum resource rent tax (PRRT) payable. Confidentiality provisions prevent the ATO providing any additional information about particular taxpayers in the report. Some entities may provide further context and explanation on their own websites. Voluntary Tax Transparency Code All corporations operating in Australia are encouraged and expected to report under the voluntary code (third link below). These reports generally include more detailed information on a corporations approach to tax and taxes paid. These reports can be accessed through the fourth link below. Changes to future reports Changes to the tax law will alter the threshold for inclusion in the corporate tax transparency report for the 2022-23 income year and onwards. The amendment changes the $200 million income threshold for Australian-owned resident private companies to $100 million. This will affect the data that will be reported in 2024 and onwards. Information on the law change can be accessed at the fifth link below.
A3: Where can you find more information?
A4: 1. Report of Entity Tax Information (2013-14 to 2021-22 datasets)
A5: 2. Corporate tax transparency reports (guidance material)
A6: 3. Voluntary Tax Transparency Code (guidance)
A7: 4. Voluntary Tax Transparency Code (reports)
A8: 5. Treasury Laws Amendment (2022 Measures No. 1) Act 2022

Sheet Income tax details
A1: Name | B1: ABN | C1: Total income $ | D1: Taxable income $ | E1: Tax payable $ | F1: Income year
A2: 1884 PTY LIMITED | B2: 83114980880 | C2: 215297043 | D2: 8124632 | E2: 2367120 | F2: 2021-22
A3: 20 CASHEWS PTY LTD | B3: 16634403124 | C3: 288582715 | D3: 36977225 | E3: 962761 | F3: 2021-22
A4: 21ST CENTURY RESORTS HOLDINGS PTY LIMITED | B4: 33104201014 | C4: 255202722 | D4: 19673962 | E4: 5902189 | F4: 2021-22
A5: 29METALS LIMITED | B5: 95650096094 | C5: 501817901 | F5: 2021-22
A6: 2SAN PTY LTD | B6: 93641633141 | C6: 739184508 | D6: 70223411 | E6: 21067023 | F6: 2021-22
A7: 3M AUSTRALIA PTY LTD | B7: 90000100096 | C7: 691305434 | D7: 22920599 | E7: 6876180 | F7: 2021-22
A8: 4CYTE PATHOLOGY PTY LTD | B8: 12619244852 | C8: 760523141 | D8: 398991550 | E8: 119697465 | F8: 2021-22
A9: 7 HOLDINGS PTY. LTD. | B9: 31005620851 | C9: 4688114379 | F9: 2021-22
A10: A. HARTRODT AUSTRALIA PTY LTD | B10: 28000640504 | C10: 137203826 | D10: 3875165 | E10: 1162550 | F10: 2021-22
A11: A.C.N. 003 933 300 PTY LTD | B11: 58003933300 | C11: 767403256 | D11: 12226618 | E11: 3667985 | F11: 2021-22
A12: A.C.N. 085 239 998 PTY LTD | B12: 39085239998 | C12: 469078115 | D12: 92455519 | E12: 26531131 | F12: 2021-22
A13: A.C.N. 113 332 942 LIMITED | B13: 99113332942 | C13: 123496898 | D13: 40474543 | E13: 10817694 | F13: 2021-22
A14: A.C.N. 116 779 876 PTY LTD | B14: 62116779876 | C14: 205230837 | F14: 2021-22
A15: A.C.N. 166 119 133 PTY LTD | B15: 31166119133 | C15: 2676985659 | F15: 2021-22
A16: A.C.N. 169 231 172 PTY LTD | B16: 34169231172 | C16: 320697915 | F16: 2021-22
A17: A.C.N. 603 303 126 PTY LTD | B17: 98603303126 | C17: 127199861 | F17: 2021-22
A18: A.C.N. 630 698 716 PTY LTD | B18: 18630698716 | C18: 147561238 | F18: 2021-22
A19: A2 AUSTRALIAN INVESTMENTS PTY. LIMITED. | B19: 93126014275 | C19: 506187163 | D19: 21624071 | E19: 6167430 | F19: 2021-22
A20: A2 INFANT NUTRITION LIMITED | B20: 81618864958 | C20: 692545136 | D20: 34182182 | E20: 10254655 | F20: 2021-22
A21: A2B AUSTRALIA LIMITED | B21: 99001958390 | C21: 124290565 | F21: 2021-22
A22: AA HOLDINGS PTY LTD | B22: 94112233744 | C22: 660833621 | D22: 44254768 | E22: 13276430 | F22: 2021-22
A23: AAPC LIMITED | B23: 87009175820 | C23: 819213185 | F23: 2021-22
A24: ABACUS GROUP HOLDINGS LIMITED | B24: 31080604619 | C24: 127412802 | F24: 2021-22
A25: ABACUS STORAGE OPERATIONS LIMITED | B25: 37112457075 | C25: 221923544 | D25: 18086649 | E25: 5425995 | F25: 2021-22
A26: ABB GROUP INVESTMENT MANAGEMENT PTY LIMITED | B26: 47082803852 | C26: 708861819 | D26: 26457921 | F26: 2021-22
A27: ABBOT POINT BULKCOAL PTY LTD | B27: 23010183534 | C27: 116222721 | D27: 8429207 | E27: 2528762 | F27: 2021-22
A28: ABBOT POINT OPERATIONS PTY LTD | B28: 58605852060 | C28: 113060899 | D28: 1262470 | E28: 378741 | F28: 2021-22
A29: ABBOTT AUSTRALASIA PTY LIMITED | B29: 95000180389 | C29: 673897302 | D29: 45995022 | E29: 13798507 | F29: 2021-22
A30: ABBVIE PTY LIMITED | B30: 48156384262 | C30: 480857852 | D30: 61821882 | E30: 9556559 | F30: 2021-22
A31: ABC REFINERY (AUSTRALIA) PTY LIMITED | B31: 86621121079 | C31: 5910596849 | D31: 19618279 | E31: 5885484 | F31: 2021-22
A32: ABC TISSUE PRODUCTS PTY LIMITED | B32: 33003085112 | C32: 499604873 | D32: 23435242 | E32: 7030573 | F32: 2021-22
A33: ABERGELDIE CONSOLIDATED PTY LTD | B33: 21143512350 | C33: 361655862 | D33: 9681894 | E33: 2904568 | F33: 2021-22
A34: ABN AMRO CLEARING SYDNEY PTY LTD | B34: 36081279889 | C34: 101017636 | D34: 7355264 | E34: 2206579 | F34: 2021-22
A35: ABN GROUP (VIC) PTY LTD | B35: 82130382188 | C35: 534197221 | D35: 5772709 | E35: 1731813 | F35: 2021-22
A36: ABN RESIDENTIAL WA PTY LTD | B36: 11008871761 | C36: 368500323 | F36: 2021-22
A37: ABP FINANCE PTY LIMITED | B37: 58139991101 | C37: 359367582 | D37: 42689204 | E37: 12806761 | F37: 2021-22
A38: ABSOLUTE EQUITY PERFORMANCE FUND LIMITED | B38: 17608552496 | C38: 237840957 | D38: 3487403 | F38: 2021-22
A39: ABT ASSOCIATES AUSTRALIA PTY LTD | B39: 72161695156 | C39: 165093717 | D39: 1245719 | E39: 373716 | F39: 2021-22
A40: ACCENT GROUP LIMITED | B40: 85108096251 | C40: 1010555341 | D40: 9941731 | E40: 2982519 | F40: 2021-22
...

Sheet PRRT details
A1: Name | B1: ABN | C1: PRRT Payable $
A2: COOPER ENERGY (CH) PTY LTD | B2: 70615355023 | C2: 4607778
A3: ESSO AUSTRALIA RESOURCES PTY LTD - BASS STRAIT | B3: 62091829819 | C3: 741286806
A4: MITSUI E&P AUSTRALIA PTY LTD | B4: 45108437529 | C4: 87793347
A5: PEEDAMULLAH PETROLEUM PTY LTD | B5: 17009363820 | C5: 8809978
A6: SANTOS (BOL) PTY LTD | B6: 35000670575 | C6: 21845003
A7: SANTOS WA NORTHWEST PTY LTD | B7: 58009140854 | C7: 114251335
A8: SANTOS WA PVG PTY LTD | B8: 51129604860 | C8: 110139574
A9: SANTOS WA SOUTHWEST PTY LTD | B9: 63050611688 | C9: 9662276
A10: VERMILION OIL & GAS AUSTRALIA PTY LTD | B10: 29113023591 | C10: 14282310
A11: WOODSIDE ENERGY (AUSTRALIA) PTY LTD | B11: 39006923879 | C11: 188679780
A12: WOODSIDE ENERGY (BASS STRAIT) PTY LTD | B12: 29004228004 | C12: 695239478

Sheet Companies for analysis
A1: Name | B1: ABN | C1: Total income $ | D1: Taxable income $ | E1: Tax payable $ | F1: Income year | H1: Effective tax rate (tax payable / taxable income) | J1: Ratio of Taxable income to Total Income
A3: COCHLEAR LIMITED | B3: 96002618073 | C3: 1296859592 | D3: 368140606 | E3: 13616051 | F3: 2021-22
A5: FLIGHT CENTRE TRAVEL GROUP LIMITED | B5: 25003377188 | C5: 495634399 | F5: 2021-22
A7: JB HI-FI LIMITED | B7: 80093220136 | C7: 8990822883 | D7: 765954031 | E7: 229786059 | F7: 2021-22
A9: QANTAS AIRWAYS LIMITED | B9: 16009661901 | C9: 9324605379 | F9: 2021-22
A11: WOOLWORTHS GROUP LIMITED | B11: 88000014675 | C11: 58136662436 | D11: 1610082986 | E11: 460957826 | F11: 2021-22
A15: APPLE PTY LTD | B15: 46002510054 | C15: 9335050508 | D15: 458656103 | E15: 137312506 | F15: 2021-22
A17: ASTRAZENECA HOLDINGS PTY LIMITED | B17: 59066876962 | C17: 1085127894 | D17: 155685431 | E17: 40390847 | F17: 2021-22
A19: FACEBOOK AUSTRALIA PTY LIMITED | B19: 83134012543 | C19: 1147348081 | D19: 100584537 | E19: 30175361 | F19: 2021-22
A21: GOOGLE AUSTRALIA PTY LIMITED | B21: 33102417032 | C21: 1789056238 | D21: 325873549 | E21: 83263425 | F21: 2021-22
A23: MICROSOFT PTY LTD | B23: 29002589460 | C23: 6296619602 | D23: 400935241 | E23: 120280572 | F23: 2021-22
A25: BHP GROUP LIMITED | B25: 49004028077 | C25: 87387398006 | D25: 40298379937 | E25: 9483568682 | F25: 2021-22
A27: HARVEY NORMAN HOLDINGS LTD | B27: 54003237545 | C27: 1968808662 | D27: 683945412 | E27: 203225274 | F27: 2021-22
A29: RIO TINTO LTD | B29: 96004458404 | C29: 55444883504 | D29: 32098258450 | E29: 9075018208 | F29: 2021-22
